Workbook

Sheet README
B2: Vahan Product Analytics Case Study
B4: Lead-Source Cohort Performance
B6: Purpose: This workbook derives every metric from the Raw Data tab supplied in the official case-study file, using auditable Excel formulas (COUNTIFS / SUMIFS) rather than hard-coded numbers. Recalculating any cell traces back to the raw rows that produced it.
B8: Analytical grain: one row in Raw Data = one lead (one candidate_phone uploaded once into one lead_source 'cohort' on one upload_date). 'Uploaded Leads' equals 1 on every row, confirming this. A candidate_phone can repeat across DIFFERENT cohorts/dates (the same person re-targeted later) but never within the same cohort, see Data_Quality tab.
B10: Cohort definition: 'lead_source' is treated as the cohort. Every lead_source in this dataset maps to a single upload batch (one upload_date, with one exception spanning two adjacent dates) so cohort and upload batch are effectively the same thing here.
B12: Funnel metric definitions (as found in Raw Data):
B13: • Lead = 1 row (Uploaded Leads = 1 for every row)
B14: • Attempted = a call attempt was made at least once (0/1)
B15: • Connected = the call connected with the candidate at least once (0/1)
B16: • tag_filled = the agent filled a call-outcome tag after connecting (0/1)
B17: • Interested = candidate was tagged 'Interested' on a call (0/1)
B18: • OB_after_upload / OB_after_first_attempt = candidate onboarded (OB), measured from upload date vs. from the first call attempt respectively
... B32: All monetary/none - this dataset contains no cost or revenue fields, so ranking is done purely on conversion metrics, not ROI.

Sheet Raw_Data
A1: upload_date | B1: lead_source | C1: candidate_phone | D1: Uploaded Leads | E1: Attempted | F1: Connected | G1: Attempt per Lead | H1: tag_filled | I1: Interested | J1: OB_after_upload | K1: OB_after_first_attempt | L1: FT_after_upload | M1: FT_after_first_attempt | N1: upload_to_first_attempt_P50 (hrs) | O1: Attempted % | P1: Attempt → Connected % | Q1: Connect → Interested % | R1: Interested → FT_after_first_attempt % | S1: Attempted → FT_after_upload % | T1: upload_date_asDate (Derived parsed from column A for date math)
A2: 2026-07-18 | B2: 2W3W - 3WAHD - Khanna - 3W - 17 Jul | C2: 91148e89d497914604c9c248ccd2aca212fac665bdc396cd2443ccc206d216e9 | D2: 1 | E2: 1 | F2: 1 | G2: 1 | H2: 1 | I2: 0 | J2: 0 | K2: 0 | L2: 0 | M2: 0 | N2: 112 | O2: 100 | P2: 100 | Q2: 0 | S2: 0 | T2: =IFERROR(DATEVALUE(A2),"") -> 46221
A3: 2026-07-18 | B3: 2W3W - 3WAHD - Khanna - 3W - 17 Jul | C3: 4aa4e7a4f4a3b9fa608c4c1729be6a8accc31f58b3d8b12bc02ad6c505f3f801 | D3: 1 | E3: 1 | F3: 0 | G3: 1 | H3: 0 | I3: 0 | J3: 0 | K3: 0 | L3: 0 | M3: 0 | N3: 112 | O3: 100 | P3: 0 | S3: 0 | T3: =IFERROR(DATEVALUE(A3),"") -> 46221
A4: 2026-07-18 | B4: 2W3W - 3WAHD - Khanna - 3W - 17 Jul | C4: 0e97e34090259c1ce6cef1fd1c491fcfc469ba9d2d1ce784d5205fc523955493 | D4: 1 | E4: 1 | F4: 0 | G4: 1 | H4: 0 | I4: 0 | J4: 0 | K4: 0 | L4: 0 | M4: 0 | N4: 89 | O4: 100 | P4: 0 | S4: 0 | T4: =IFERROR(DATEVALUE(A4),"") -> 46221
A5: 2026-07-18 | B5: 2W3W - 3WAHD - Khanna - 3W - 17 Jul | C5: cdc003718802cffa769a478bcc0fe31aa20ac3ffe97a7c0f3c6738a2105fa08b | D5: 1 | E5: 1 | F5: 0 | G5: 1 | H5: 0 | I5: 0 | J5: 0 | K5: 0 | L5: 0 | M5: 0 | N5: 106 | O5: 100 | P5: 0 | S5: 0 | T5: =IFERROR(DATEVALUE(A5),"") -> 46221
A6: 2026-07-18 | B6: 2W3W - 3WAHD - Khanna - 3W - 17 Jul | C6: d70833a770ab63e1992254dad148b100bbbadbe0e946736e9feb33252b728819 | D6: 1 | E6: 1 | F6: 0 | G6: 1 | H6: 0 | I6: 0 | J6: 0 | K6: 0 | L6: 0 | M6: 0 | N6: 90 | O6: 100 | P6: 0 | S6: 0 | T6: =IFERROR(DATEVALUE(A6),"") -> 46221
A7: 2026-07-18 | B7: 2W3W - 3WAHD - Khanna - 3W - 17 Jul | C7: 1d9d97944c72a161dc845aef65f36c83039a23881ec3bd102288fa2f571a8e68 | D7: 1 | E7: 1 | F7: 1 | G7: 1 | H7: 1 | I7: 0 | J7: 0 | K7: 0 | L7: 0 | M7: 0 | N7: 108 | O7: 100 | P7: 100 | Q7: 0 | S7: 0 | T7: =IFERROR(DATEVALUE(A7),"") -> 46221
A8: 2026-07-18 | B8: 2W3W - 3WAHD - Khanna - 3W - 17 Jul | C8: e813ab89059a38332bd912820ae1622829c295f3c7cbe8a0499b994d1014cd7d | D8: 1 | E8: 1 | F8: 1 | G8: 1 | H8: 1 | I8: 0 | J8: 0 | K8: 0 | L8: 0 | M8: 0 | N8: 84 | O8: 100 | P8: 100 | Q8: 0 | S8: 0 | T8: =IFERROR(DATEVALUE(A8),"") -> 46221
A9: 2026-07-18 | B9: 2W3W - 3WAHD - Khanna - 3W - 17 Jul | C9: 643f68b96fa4fb591142d7bcbad6e045d9ceaed52cf703ffa1ef5b6684d93196 | D9: 1 | E9: 1 | F9: 0 | G9: 1 | H9: 0 | I9: 0 | J9: 0 | K9: 0 | L9: 0 | M9: 0 | N9: 110 | O9: 100 | P9: 0 | S9: 0 | T9: =IFERROR(DATEVALUE(A9),"") -> 46221
A10: 2026-07-18 | B10: 2W3W - 3WAHD - Khanna - 3W - 17 Jul | C10: 4ff90c095485968a336cd4e52902d4c0b6b56ed5da9fd28500a8525e07cfd455 | D10: 1 | E10: 1 | F10: 1 | G10: 1 | H10: 1 | I10: 0 | J10: 0 | K10: 0 | L10: 0 | M10: 0 | N10: 88 | O10: 100 | P10: 100 | Q10: 0 | S10: 0 | T10: =IFERROR(DATEVALUE(A10),"") -> 46221
A11: 2026-07-18 | B11: 2W3W - 3WAHD - Khanna - 3W - 17 Jul | C11: 3686d8ba819b963abb8198bc7f13bd663af40875d8ecf093ffe547a04b1b3d46 | D11: 1 | E11: 1 | F11: 0 | G11: 1 | H11: 0 | I11: 0 | J11: 0 | K11: 0 | L11: 0 | M11: 0 | N11: 89 | O11: 100 | P11: 0 | S11: 0 | T11: =IFERROR(DATEVALUE(A11),"") -> 46221
A12: 2026-07-18 | B12: 2W3W - 3WAHD - Khanna - 3W - 17 Jul | C12: 687f6cf5eedbfc6450a9068c710c13885f3e296f6ddf6c562ee284a630c3d11e | D12: 1 | E12: 1 | F12: 0 | G12: 1 | H12: 0 | I12: 0 | J12: 0 | K12: 0 | L12: 0 | M12: 0 | N12: 107 | O12: 100 | P12: 0 | S12: 0 | T12: =IFERROR(DATEVALUE(A12),"") -> 46221
A13: 2026-07-18 | B13: 2W3W - 3WAHD - Khanna - 3W - 17 Jul | C13: 03be102bdd3bc1016b64f162808ceb7c8fabbb34656da615063f16a9b9d692ee | D13: 1 | E13: 1 | F13: 0 | G13: 1 | H13: 0 | I13: 0 | J13: 0 | K13: 0 | L13: 0 | M13: 0 | N13: 111 | O13: 100 | P13: 0 | S13: 0 | T13: =IFERROR(DATEVALUE(A13),"") -> 46221
A14: 2026-07-18 | B14: 2W3W - 3WAHD - Khanna - 3W - 17 Jul | C14: 61a7bbc8009cfc0e46fcb69ba9a430a55377daeb1cf385cf3130aa5989aa65db | D14: 1 | E14: 1 | F14: 0 | G14: 1 | H14: 0 | I14: 0 | J14: 0 | K14: 0 | L14: 0 | M14: 0 | N14: 114 | O14: 100 | P14: 0 | S14: 0 | T14: =IFERROR(DATEVALUE(A14),"") -> 46221
A15: 2026-07-18 | B15: 2W3W - 3WAHD - Khanna - 3W - 17 Jul | C15: c61f9d77891d210d28fa6b5f61cb2974f9e96fd6c18b136b7c8bcf67eeaf4d1a | D15: 1 | E15: 1 | F15: 0 | G15: 1 | H15: 0 | I15: 0 | J15: 0 | K15: 0 | L15: 0 | M15: 0 | N15: 129 | O15: 100 | P15: 0 | S15: 0 | T15: =IFERROR(DATEVALUE(A15),"") -> 46221
A16: 2026-07-18 | B16: 2W3W - 3WAHD - Khanna - 3W - 17 Jul | C16: 2c75c32d3bea7b49d7ddb030d25ef480df748b7c94c24437c2b7d9fd7550ae2e | D16: 1 | E16: 1 | F16: 1 | G16: 2 | H16: 1 | I16: 0 | J16: 0 | K16: 0 | L16: 0 | M16: 0 | N16: 266.5 | O16: 100 | P16: 100 | Q16: 0 | S16: 0 | T16: =IFERROR(DATEVALUE(A16),"") -> 46221
A17: 2026-07-18 | B17: 2W3W - 3WAHD - Khanna - 3W - 17 Jul | C17: d0361cbe1a5b3497a86b1362bc302fc95cca25eb1bf73977b03a38ea52a2f92d | D17: 1 | E17: 1 | F17: 1 | G17: 1 | H17: 1 | I17: 0 | J17: 0 | K17: 0 | L17: 0 | M17: 0 | N17: 90 | O17: 100 | P17: 100 | Q17: 0 | S17: 0 | T17: =IFERROR(DATEVALUE(A17),"") -> 46221
A18: 2026-07-18 | B18: 2W3W - 3WAHD - Khanna - 3W - 17 Jul | C18: 67ed3e8db9fc6244fddf4c2e2b47b2c2c205cd467037d778c2273d97c8684616 | D18: 1 | E18: 1 | F18: 0 | G18: 1 | H18: 0 | I18: 0 | J18: 0 | K18: 0 | L18: 0 | M18: 0 | N18: 129 | O18: 100 | P18: 0 | S18: 0 | T18: =IFERROR(DATEVALUE(A18),"") -> 46221
A19: 2026-07-18 | B19: 2W3W - 3WAHD - Khanna - 3W - 17 Jul | C19: 988e43a67660399b59f561e84439a64ad60e95803a0ef34e193f4a77fd84a397 | D19: 1 | E19: 1 | F19: 1 | G19: 2 | H19: 1 | I19: 0 | J19: 0 | K19: 0 | L19: 0 | M19: 0 | N19: 279 | O19: 100 | P19: 100 | Q19: 0 | S19: 0 | T19: =IFERROR(DATEVALUE(A19),"") -> 46221
A20: 2026-07-18 | B20: 2W3W - 3WAHD - Khanna - 3W - 17 Jul | C20: 7642b7ef457db0510517dcc2d283e0e20ec0153e7c2ad582f291826986a88fb0 | D20: 1 | E20: 1 | F20: 1 | G20: 1 | H20: 1 | I20: 0 | J20: 0 | K20: 0 | L20: 0 | M20: 0 | N20: 113 | O20: 100 | P20: 100 | Q20: 0 | S20: 0 | T20: =IFERROR(DATEVALUE(A20),"") -> 46221
A21: 2026-07-18 | B21: 2W3W - 3WAHD - Khanna - 3W - 17 Jul | C21: a9fc85acc78f954c914b15b8f2d58cfabecd70f02e9cf96418ef1252cc5d051c | D21: 1 | E21: 1 | F21: 0 | G21: 1 | H21: 0 | I21: 0 | J21: 0 | K21: 0 | L21: 0 | M21: 0 | N21: 88 | O21: 100 | P21: 0 | S21: 0 | T21: =IFERROR(DATEVALUE(A21),"") -> 46221
A22: 2026-07-18 | B22: 2W3W - 3WAHD - Khanna - 3W - 17 Jul | C22: 9be95999adc49484937d887489dc50ef0f8147945f1a86acfedeafd8ec7326db | D22: 1 | E22: 1 | F22: 1 | G22: 2 | H22: 1 | I22: 0 | J22: 0 | K22: 0 | L22: 0 | M22: 0 | N22: 266 | O22: 100 | P22: 100 | Q22: 0 | S22: 0 | T22: =IFERROR(DATEVALUE(A22),"") -> 46221
A23: 2026-07-18 | B23: 2W3W - 3WAHD - Khanna - 3W - 17 Jul | C23: 6d833a01ea37bd0facc0f94748558bc23989640261bffb5adb8c6d2709a08165 | D23: 1 | E23: 1 | F23: 1 | G23: 1 | H23: 1 | I23: 0 | J23: 0 | K23: 0 | L23: 0 | M23: 0 | N23: 111 | O23: 100 | P23: 100 | Q23: 0 | S23: 0 | T23: =IFERROR(DATEVALUE(A23),"") -> 46221
A24: 2026-07-18 | B24: 2W3W - 3WAHD - Khanna - 3W - 17 Jul | C24: a466e3191335d011f2fb9a866c9e65764cbda7d6b103d53934033514125f76a8 | D24: 1 | E24: 1 | F24: 0 | G24: 1 | H24: 0 | I24: 0 | J24: 0 | K24: 0 | L24: 0 | M24: 0 | N24: 88 | O24: 100 | P24: 0 | S24: 0 | T24: =IFERROR(DATEVALUE(A24),"") -> 46221
A25: 2026-07-18 | B25: 2W3W - 3WAHD - Khanna - 3W - 17 Jul | C25: fb46aac2117e9c2ee6bbc171c6e78e2e6956af583bdb88dd4b457c7d7239c82c | D25: 1 | E25: 1 | F25: 0 | G25: 1 | H25: 0 | I25: 0 | J25: 0 | K25: 0 | L25: 0 | M25: 0 | N25: 88 | O25: 100 | P25: 0 | S25: 0 | T25: =IFERROR(DATEVALUE(A25),"") -> 46221
A26: 2026-07-18 | B26: 2W3W - 3WAHD - Khanna - 3W - 17 Jul | C26: 4cdac9304c27d05ee01dbcae7de19d17dc38a22b54cf953ddf5e30d133f08cfb | D26: 1 | E26: 1 | F26: 0 | G26: 1 | H26: 0 | I26: 0 | J26: 0 | K26: 0 | L26: 0 | M26: 0 | N26: 112 | O26: 100 | P26: 0 | S26: 0 | T26: =IFERROR(DATEVALUE(A26),"") -> 46221
A27: 2026-07-18 | B27: 2W3W - 3WAHD - Khanna - 3W - 17 Jul | C27: 8d1ade5808fd039b889659a95150ae86145a6e50e96f41e0efa4aabeb7df5481 | D27: 1 | E27: 1 | F27: 0 | G27: 1 | H27: 0 | I27: 0 | J27: 0 | K27: 0 | L27: 0 | M27: 0 | N27: 84 | O27: 100 | P27: 0 | S27: 0 | T27: =IFERROR(DATEVALUE(A27),"") -> 46221
A28: 2026-07-18 | B28: 2W3W - 3WAHD - Khanna - 3W - 17 Jul | C28: f6092b655b0091cbb95144f82f4986c2f9a343a22d2888a2450c9e1086524d6a | D28: 1 | E28: 1 | F28: 0 | G28: 1 | H28: 0 | I28: 0 | J28: 0 | K28: 0 | L28: 0 | M28: 0 | N28: 87 | O28: 100 | P28: 0 | S28: 0 | T28: =IFERROR(DATEVALUE(A28),"") -> 46221
A29: 2026-07-18 | B29: 2W3W - 3WAHD - Khanna - 3W - 17 Jul | C29: 9d1c8d7159e619c271847a6874f03514d5a99dd0cba7600ebb6c9edf559f4279 | D29: 1 | E29: 1 | F29: 0 | G29: 1 | H29: 0 | I29: 0 | J29: 0 | K29: 0 | L29: 0 | M29: 0 | N29: 110 | O29: 100 | P29: 0 | S29: 0 | T29: =IFERROR(DATEVALUE(A29),"") -> 46221
A30: 2026-07-18 | B30: 2W3W - 3WAHD - Khanna - 3W - 17 Jul | C30: cf482975e2b3a9ec0173e27a5eb66b72fa78bded1a13d7164eef3fe1a41b5a05 | D30: 1 | E30: 1 | F30: 1 | G30: 1 | H30: 1 | I30: 0 | J30: 0 | K30: 0 | L30: 0 | M30: 0 | N30: 106 | O30: 100 | P30: 100 | Q30: 0 | S30: 0 | T30: =IFERROR(DATEVALUE(A30),"") -> 46221
A31: 2026-07-18 | B31: 2W3W - 3WAHD - Khanna - 3W - 17 Jul | C31: 8c42ae57d548bf07a0a3feff026d5254b664c1df1dc2d87e644024a33d7aae04 | D31: 1 | E31: 1 | F31: 0 | G31: 1 | H31: 0 | I31: 0 | J31: 0 | K31: 0 | L31: 0 | M31: 0 | N31: 84 | O31: 100 | P31: 0 | S31: 0 | T31: =IFERROR(DATEVALUE(A31),"") -> 46221
A32: 2026-07-18 | B32: 2W3W - 3WAHD - Khanna - 3W - 17 Jul | C32: b84a8500a0b79a62833e87b15473be8e0c2b97ca708c73d21ed58d5449524729 | D32: 1 | E32: 1 | F32: 0 | G32: 1 | H32: 0 | I32: 0 | J32: 0 | K32: 0 | L32: 0 | M32: 0 | N32: 90 | O32: 100 | P32: 0 | S32: 0 | T32: =IFERROR(DATEVALUE(A32),"") -> 46221
A33: 2026-07-18 | B33: 2W3W - 3WAHD - Khanna - 3W - 17 Jul | C33: 7cafc314bc0b3e42a8613cc53cb203f5d197f92da5387a160bcd75107eeb2311 | D33: 1 | E33: 1 | F33: 1 | G33: 2 | H33: 1 | I33: 1 | J33: 0 | K33: 0 | L33: 0 | M33: 0 | N33: 278.5 | O33: 100 | P33: 100 | Q33: 100 | R33: 0 | S33: 0 | T33: =IFERROR(DATEVALUE(A33),"") -> 46221
A34: 2026-07-18 | B34: 2W3W - 3WAHD - Khanna - 3W - 17 Jul | C34: ea82511e8802bd149468aab83ebb91b8965f71a46715f87348b963ce3a592072 | D34: 1 | E34: 1 | F34: 1 | G34: 1 | H34: 1 | I34: 0 | J34: 0 | K34: 0 | L34: 0 | M34: 0 | N34: 106 | O34: 100 | P34: 100 | Q34: 0 | S34: 0 | T34: =IFERROR(DATEVALUE(A34),"") -> 46221
A35: 2026-07-18 | B35: 2W3W - 3WAHD - Khanna - 3W - 17 Jul | C35: 3100e51e81947a07ef6ffbdb1bf6971f6e375940740cd9c7460eaa28c8ec0dd1 | D35: 1 | E35: 1 | F35: 0 | G35: 1 | H35: 0 | I35: 0 | J35: 0 | K35: 0 | L35: 0 | M35: 0 | N35: 108 | O35: 100 | P35: 0 | S35: 0 | T35: =IFERROR(DATEVALUE(A35),"") -> 46221
A36: 2026-07-18 | B36: 2W3W - 3WAHD - Khanna - 3W - 17 Jul | C36: 3fc13c1a3aedf7f076f72f293d08d2bed6fbc914c826ad3df7e4637c724430bb | D36: 1 | E36: 1 | F36: 0 | G36: 1 | H36: 0 | I36: 0 | J36: 0 | K36: 0 | L36: 0 | M36: 0 | N36: 88 | O36: 100 | P36: 0 | S36: 0 | T36: =IFERROR(DATEVALUE(A36),"") -> 46221
A37: 2026-07-18 | B37: 2W3W - 3WAHD - Khanna - 3W - 17 Jul | C37: 3804ac4bd4e156f94676998ad65f88623b3ddf58eb1bbc60b4cf8d72ed65614f | D37: 1 | E37: 1 | F37: 0 | G37: 1 | H37: 0 | I37: 0 | J37: 0 | K37: 0 | L37: 0 | M37: 0 | N37: 88 | O37: 100 | P37: 0 | S37: 0 | T37: =IFERROR(DATEVALUE(A37),"") -> 46221
A38: 2026-07-18 | B38: 2W3W - 3WAHD - Khanna - 3W - 17 Jul | C38: 693a0c205b53678205bf4d0e5950183cec07f4a9d358482de6b4185cd5991f7f | D38: 1 | E38: 1 | F38: 0 | G38: 1 | H38: 0 | I38: 0 | J38: 0 | K38: 0 | L38: 0 | M38: 0 | N38: 107 | O38: 100 | P38: 0 | S38: 0 | T38: =IFERROR(DATEVALUE(A38),"") -> 46221
A39: 2026-07-18 | B39: 2W3W - 3WAHD - Khanna - 3W - 17 Jul | C39: 05c03e84047f07a2d32228c2dd1aac7f21469eaa6ba806c00c809f10714c2893 | D39: 1 | E39: 1 | F39: 1 | G39: 1 | H39: 1 | I39: 0 | J39: 0 | K39: 0 | L39: 0 | M39: 0 | N39: 113 | O39: 100 | P39: 100 | Q39: 0 | S39: 0 | T39: =IFERROR(DATEVALUE(A39),"") -> 46221
A40: 2026-07-18 | B40: 2W3W - 3WAHD - Khanna - 3W - 17 Jul | C40: d83000eb7882ad63b469b559d19181819c98e378fe47c488378b5a00589e7524 | D40: 1 | E40: 1 | F40: 1 | G40: 2 | H40: 1 | I40: 0 | J40: 0 | K40: 0 | L40: 0 | M40: 0 | N40: 266 | O40: 100 | P40: 100 | Q40: 0 | S40: 0 | T40: =IFERROR(DATEVALUE(A40),"") -> 46221
...

Sheet Data_Quality
B2: Data Quality & Assumptions
B4: Live counts (formulas reference Raw_Data; recalculate automatically if raw data changes)
B6: Issue | C6: Evidence | D6: Treatment | E6: Reason | F6: Live Count
B7: Missing candidate_phone | C7: 1 row has a blank candidate_phone (row with upload_date 2026-07-29, cohort 'PreOb-Ob Fees Paid 29th Jul (set 1)'). | D7: Excluded from candidate-level dedup / re-targeting checks; kept in all cohort and funnel aggregates since lead_source, upload_date and every funnel flag are populated and valid for that row. | E7: Cohort and funnel metrics do not depend on candidate_phone being present; only phone-level uniqueness checks do, so exclusion there avoids a false 'unique candidate' count without discarding a real lead. | F7: =COUNTBLANK(Raw_Data!C2:C18199) -> 1
B8: Duplicate candidate_phone across cohorts | C8: 1,100 rows share a candidate_phone with at least one other row; in every case the duplicate rows belong to DIFFERENT lead_source/upload_date combinations (0 true same-cohort duplicates). | D8: Not deduplicated. Each row is kept as its own lead/upload event for cohort and funnel analysis. | E8: The case defines the unit of analysis as leads sourced into a cohort, not unique people. A person re-targeted into a new campaign after an earlier attempt is a new, independent business event (new call attempt, new cost, new outcome chance) and must count in that cohort's funnel. | F8: =18198-COUNTBLANK(Raw_Data!C2:C18199)-17097 -> 1100
B9: 'Interested' does not gate OB / FT | C9: 116 of 119 OB_after_upload=1 rows, and 53 of 54 FT_after_upload=1 rows, have Interested=0 most conversions bypass the Interested tag entirely. | D9: Interested is reported as a descriptive/process metric only, never treated as a required funnel checkpoint or a hard gate in the funnel chart; a footnote flags the resulting 'Interested → FT' rate as not meaningful in isolation. | E9: Interested is agent-entered call-tagging behavior, which this data shows is applied inconsistently across cohorts (see Cohort_Analysis 'interest_rate' column, which ranges from <1% to ~16% with no clear link to actual FT rate). Treating it as a strict funnel stage would understate true conversion. | F9: =COUNTIFS(Raw_Data!J2:J18199,1,Raw_Data!I2:I18199,0) -> 116
B10: Right-censored / immature cohorts | C10: Cohorts uploaded within the last few days of the data (e.g. 'Khanna AI' uploaded on the latest date in the file) show 0 or very low FT, but FT elsewhere in the data takes well over a week to register. | D10: Cohort ranking (Cohort_Analysis, Top-3) restricted to cohorts with age >= 5 days since upload, computed as MAX(upload_date in file) - cohort's upload_date. | E10: Comparing a 0-day-old cohort's FT rate to a 19-day-old cohort's FT rate on equal footing would wrongly penalize the newest cohort for not yet having had time to convert (right-censoring bias). | F10: =SUMPRODUCT((MAX(Raw_Data!T2:T18199)-Raw_Data!T2:T18199<5)*1) -> 4216
B11: Tiny / single-lead cohorts | C11: 5 of 16 lead_source values have fewer than 5 leads each (as low as 1 lead). | D11: Excluded from the Top-3 cohort ranking (minimum-size filter: leads >= 1,000, justified in Cohort_Analysis) but left visible in the full cohort table for completeness. | E11: A conversion rate computed on 1-3 leads is a single-event artifact, not a stable estimate; ranking on it would be statistically indefensible. | F11: see Cohort_Analysis
B12: Zero-denominator risk in rate formulas | C12: Attempted, Connected and Interested can each legitimately be 0 for a cohort (e.g. a brand-new upload with 0 attempts so far), which would divide by zero in connect-rate / interest-rate formulas. | D12: Every rate formula in Funnel_Analysis and Cohort_Analysis is wrapped in IFERROR(...,"n/a") or tested for a zero denominator before dividing. | E12: Prevents #DIV/0! errors from breaking the workbook and makes 'not yet computable' explicit instead of silently showing 0%. | F12: n/a
B13: FT_after_first_attempt is a strict subset of FT_after_upload | C13: Every row with FT_after_first_attempt=1 also has FT_after_upload=1 (0 exceptions); same holds for OB_after_first_attempt vs OB_after_upload. | D13: Confirms the two FT/OB fields are nested definitions of the same event (narrower vs. wider time window), not independent outcomes. FT_after_upload used as the primary 'did this lead convert' metric since it is the more complete count (54 vs. 17 events); FT_after_first_attempt used only for speed-to-convert framing. | E13: Validates that FT_after_upload is safe to use as the headline conversion metric without double-counting or contradicting the narrower measure. | F13: =COUNTIFS(Raw_Data!M2:M18199,1,Raw_Data!L2:L18199,0) -> 0
B14: 'Attempted %', stage-conversion % columns are pre-computed, per-row duplicates of the 0/1 flags | C14: Columns O-S in Raw_Data (Attempted %, Attempt→Connected %, etc.) restate the same information as columns E-M at the single-lead level and are frequently blank (e.g. Connect→Interested % is blank on 94.9% of rows because Interested is usually 0 or Connected is 0). | D14: Not used as a data source for any aggregate metric in this workbook; all cohort/funnel rates are recomputed from the underlying 0/1 flags using SUMIFS/COUNTIFS. | E14: A per-row percentage cannot be correctly averaged into a cohort-level rate (that would weight every lead equally regardless of whether it was even attempted); the 0/1 flags must be summed first. | F14: n/a

Sheet Funnel_Analysis
B2: Funnel Analysis: Overall (All Cohorts Combined)
B4: Stage | C4: Count | D4: % of Previous Stage | E4: % of Total Leads
B5: Lead (total rows) | C5: =COUNTA(Raw_Data!D2:D18199) -> 18198 | D5: - | E5: =1 -> 1
B6: Attempted | C6: =SUM(Raw_Data!E2:E18199) -> 11973 | D6: =C6/C5 -> 0.65792944 | E6: =C6/C5 -> 0.65792944
B7: Connected | C7: =SUM(Raw_Data!F2:F18199) -> 5550 | D7: =IFERROR(C7/C6,"n/a") -> 0.46354297 | E7: =C7/C5 -> 0.30497857
B8: Interested | C8: =SUM(Raw_Data!I2:I18199) -> 348 | D8: =IFERROR(C8/C7,"n/a") -> 0.062702703 | E8: =C8/C5 -> 0.019122981
B9: OB_after_upload | C9: =SUM(Raw_Data!J2:J18199) -> 119 | D9: =IFERROR(C9/C8,"n/a") -> 0.34195402 | E9: =C9/C5 -> 0.0065391801
B10: FT_after_upload | C10: =SUM(Raw_Data!L2:L18199) -> 54 | D10: =IFERROR(C10/C9,"n/a") -> 0.45378151 | E10: =C10/C5 -> 0.0029673591
B12: Caution: 'OB_after_upload / of Interested' overstates the true OB gate because most OB events (116 of 119) occur WITHOUT Interested ever being set to 1; see Data_Quality tab. The '% of Total Leads' column is the reliable, path-independent view of every stage.
B15: Largest Absolute Drop-offs (vs. Total Leads)
B16: Transition | C16: Leads Lost | D16: % of Total Leads Lost
B17: Lead → Attempted (never called) | C17: =C5-C6 -> 6225 | D17: =(C5-C6)/C5 -> 0.34207056
B18: Attempted → Connected (no answer) | C18: =C6-C7 -> 6423 | D18: =(C6-C7)/C5 -> 0.35295087
B19: Connected → Interested (tag not positive) | C19: =C7-C8 -> 5202 | D19: =(C7-C8)/C5 -> 0.28585559
B20: Interested-stage → OB | C20: =C8-C9 -> 229 | D20: =(C8-C9)/C5 -> 0.0125838
B21: OB → FT | C21: =C9-C10 -> 65 | D21: =(C9-C10)/C5 -> 0.0035718211
B23: Reading: the single largest lever for FT volume is getting leads attempted at all over a third of leads (see 'Lead → Attempted' row) are never called even once. This is fully within operational control, unlike Attempted → Connected, which partly depends on candidate availability.

Sheet Cohort_Analysis
B2: Cohort-Level Aggregate Table
B3: Aggregation grain: lead_source (cohort) — every cohort here is a single upload batch (see README).
B5: lead_source (cohort) | C5: Upload Date | D5: Age (days) | E5: Leads | F5: Attempted | G5: Connected | H5: Interested | I5: FT_after_upload | J5: Attempt Rate | K5: Connect Rate | L5: Interest Rate | M5: Lead→FT %
B6: 2W3W - 3WAHD - Khanna - 3W - 17 Jul | C6: =_xlfn.MINIFS(Raw_Data!T2:T18199,Raw_Data!B2:B18199,B6) -> 46221 | D6: =MAX(Raw_Data!T2:T18199)-C6 -> 19 | E6: =COUNTIF(Raw_Data!B2:B18199,B6) -> 495 | F6: =SUMIFS(Raw_Data!E2:E18199,Raw_Data!B2:B18199,B6) -> 495 | G6: =SUMIFS(Raw_Data!F2:F18199,Raw_Data!B2:B18199,B6) -> 212 | H6: =SUMIFS(Raw_Data!I2:I18199,Raw_Data!B2:B18199,B6) -> 7 | I6: =SUMIFS(Raw_Data!L2:L18199,Raw_Data!B2:B18199,B6) -> 0 | J6: =IFERROR(F6/E6,"n/a") -> 1 | K6: =IFERROR(G6/F6,"n/a") -> 0.42828283 | L6: =IFERROR(H6/G6,"n/a") -> 0.033018868 | M6: =IFERROR(I6/E6,"n/a") -> 0
B7: 2W3W - 3WCNG - Khanna - 3W - 17 Jul | C7: =_xlfn.MINIFS(Raw_Data!T2:T18199,Raw_Data!B2:B18199,B7) -> 46221 | D7: =MAX(Raw_Data!T2:T18199)-C7 -> 19 | E7: =COUNTIF(Raw_Data!B2:B18199,B7) -> 530 | F7: =SUMIFS(Raw_Data!E2:E18199,Raw_Data!B2:B18199,B7) -> 530 | G7: =SUMIFS(Raw_Data!F2:F18199,Raw_Data!B2:B18199,B7) -> 291 | H7: =SUMIFS(Raw_Data!I2:I18199,Raw_Data!B2:B18199,B7) -> 1 | I7: =SUMIFS(Raw_Data!L2:L18199,Raw_Data!B2:B18199,B7) -> 0 | J7: =IFERROR(F7/E7,"n/a") -> 1 | K7: =IFERROR(G7/F7,"n/a") -> 0.5490566 | L7: =IFERROR(H7/G7,"n/a") -> 0.0034364261 | M7: =IFERROR(I7/E7,"n/a") -> 0
B8: 2W3W - 3WEV - Khanna - 3W - 17 Jul | C8: =_xlfn.MINIFS(Raw_Data!T2:T18199,Raw_Data!B2:B18199,B8) -> 46221 | D8: =MAX(Raw_Data!T2:T18199)-C8 -> 19 | E8: =COUNTIF(Raw_Data!B2:B18199,B8) -> 201 | F8: =SUMIFS(Raw_Data!E2:E18199,Raw_Data!B2:B18199,B8) -> 201 | G8: =SUMIFS(Raw_Data!F2:F18199,Raw_Data!B2:B18199,B8) -> 91 | H8: =SUMIFS(Raw_Data!I2:I18199,Raw_Data!B2:B18199,B8) -> 1 | I8: =SUMIFS(Raw_Data!L2:L18199,Raw_Data!B2:B18199,B8) -> 0 | J8: =IFERROR(F8/E8,"n/a") -> 1 | K8: =IFERROR(G8/F8,"n/a") -> 0.45273632 | L8: =IFERROR(H8/G8,"n/a") -> 0.010989011 | M8: =IFERROR(I8/E8,"n/a") -> 0
B9: 50K 2W4 - Khanna - 2W - 17 Jul | C9: =_xlfn.MINIFS(Raw_Data!T2:T18199,Raw_Data!B2:B18199,B9) -> 46221 | D9: =MAX(Raw_Data!T2:T18199)-C9 -> 19 | E9: =COUNTIF(Raw_Data!B2:B18199,B9) -> 1 | F9: =SUMIFS(Raw_Data!E2:E18199,Raw_Data!B2:B18199,B9) -> 1 | G9: =SUMIFS(Raw_Data!F2:F18199,Raw_Data!B2:B18199,B9) -> 1 | H9: =SUMIFS(Raw_Data!I2:I18199,Raw_Data!B2:B18199,B9) -> 0 | I9: =SUMIFS(Raw_Data!L2:L18199,Raw_Data!B2:B18199,B9) -> 0 | J9: =IFERROR(F9/E9,"n/a") -> 1 | K9: =IFERROR(G9/F9,"n/a") -> 1 | L9: =IFERROR(H9/G9,"n/a") -> 0 | M9: =IFERROR(I9/E9,"n/a") -> 0
B10: 50K 2W5 - Khanna - 2W - 17 Jul | C10: =_xlfn.MINIFS(Raw_Data!T2:T18199,Raw_Data!B2:B18199,B10) -> 46224 | D10: =MAX(Raw_Data!T2:T18199)-C10 -> 16 | E10: =COUNTIF(Raw_Data!B2:B18199,B10) -> 1 | F10: =SUMIFS(Raw_Data!E2:E18199,Raw_Data!B2:B18199,B10) -> 0 | G10: =SUMIFS(Raw_Data!F2:F18199,Raw_Data!B2:B18199,B10) -> 0 | H10: =SUMIFS(Raw_Data!I2:I18199,Raw_Data!B2:B18199,B10) -> 0 | I10: =SUMIFS(Raw_Data!L2:L18199,Raw_Data!B2:B18199,B10) -> 0 | J10: =IFERROR(F10/E10,"n/a") -> 0 | K10: =IFERROR(G10/F10,"n/a") -> n/a | L10: =IFERROR(H10/G10,"n/a") -> n/a | M10: =IFERROR(I10/E10,"n/a") -> 0
B11: AI Connected band Not Interested | C11: =_xlfn.MINIFS(Raw_Data!T2:T18199,Raw_Data!B2:B18199,B11) -> 46238 | D11: =MAX(Raw_Data!T2:T18199)-C11 -> 2 | E11: =COUNTIF(Raw_Data!B2:B18199,B11) -> 2137 | F11: =SUMIFS(Raw_Data!E2:E18199,Raw_Data!B2:B18199,B11) -> 1359 | G11: =SUMIFS(Raw_Data!F2:F18199,Raw_Data!B2:B18199,B11) -> 637 | H11: =SUMIFS(Raw_Data!I2:I18199,Raw_Data!B2:B18199,B11) -> 21 | I11: =SUMIFS(Raw_Data!L2:L18199,Raw_Data!B2:B18199,B11) -> 0 | J11: =IFERROR(F11/E11,"n/a") -> 0.63593823 | K11: =IFERROR(G11/F11,"n/a") -> 0.46872701 | L11: =IFERROR(H11/G11,"n/a") -> 0.032967033 | M11: =IFERROR(I11/E11,"n/a") -> 0
B12: AI Connected but not Connected by TC- Set 1 | C12: =_xlfn.MINIFS(Raw_Data!T2:T18199,Raw_Data!B2:B18199,B12) -> 46235 | D12: =MAX(Raw_Data!T2:T18199)-C12 -> 5 | E12: =COUNTIF(Raw_Data!B2:B18199,B12) -> 1480 | F12: =SUMIFS(Raw_Data!E2:E18199,Raw_Data!B2:B18199,B12) -> 1331 | G12: =SUMIFS(Raw_Data!F2:F18199,Raw_Data!B2:B18199,B12) -> 694 | H12: =SUMIFS(Raw_Data!I2:I18199,Raw_Data!B2:B18199,B12) -> 29 | I12: =SUMIFS(Raw_Data!L2:L18199,Raw_Data!B2:B18199,B12) -> 5 | J12: =IFERROR(F12/E12,"n/a") -> 0.89932432 | K12: =IFERROR(G12/F12,"n/a") -> 0.52141247 | L12: =IFERROR(H12/G12,"n/a") -> 0.041786744 | M12: =IFERROR(I12/E12,"n/a") -> 0.0033783784
B13: AI Connected but not Connected by TC- Set 2 | C13: =_xlfn.MINIFS(Raw_Data!T2:T18199,Raw_Data!B2:B18199,B13) -> 46237 | D13: =MAX(Raw_Data!T2:T18199)-C13 -> 3 | E13: =COUNTIF(Raw_Data!B2:B18199,B13) -> 1193 | F13: =SUMIFS(Raw_Data!E2:E18199,Raw_Data!B2:B18199,B13) -> 1066 | G13: =SUMIFS(Raw_Data!F2:F18199,Raw_Data!B2:B18199,B13) -> 466 | H13: =SUMIFS(Raw_Data!I2:I18199,Raw_Data!B2:B18199,B13) -> 26 | I13: =SUMIFS(Raw_Data!L2:L18199,Raw_Data!B2:B18199,B13) -> 2 | J13: =IFERROR(F13/E13,"n/a") -> 0.89354568 | K13: =IFERROR(G13/F13,"n/a") -> 0.43714822 | L13: =IFERROR(H13/G13,"n/a") -> 0.055793991 | M13: =IFERROR(I13/E13,"n/a") -> 0.0016764459
B14: JobHai - Khanna - Riders - 16 Jul | C14: =_xlfn.MINIFS(Raw_Data!T2:T18199,Raw_Data!B2:B18199,B14) -> 46224 | D14: =MAX(Raw_Data!T2:T18199)-C14 -> 16 | E14: =COUNTIF(Raw_Data!B2:B18199,B14) -> 2 | F14: =SUMIFS(Raw_Data!E2:E18199,Raw_Data!B2:B18199,B14) -> 0 | G14: =SUMIFS(Raw_Data!F2:F18199,Raw_Data!B2:B18199,B14) -> 0 | H14: =SUMIFS(Raw_Data!I2:I18199,Raw_Data!B2:B18199,B14) -> 0 | I14: =SUMIFS(Raw_Data!L2:L18199,Raw_Data!B2:B18199,B14) -> 0 | J14: =IFERROR(F14/E14,"n/a") -> 0 | K14: =IFERROR(G14/F14,"n/a") -> n/a | L14: =IFERROR(H14/G14,"n/a") -> n/a | M14: =IFERROR(I14/E14,"n/a") -> 0
B15: JobHai - Khanna - Riders - 17 Jul | C15: =_xlfn.MINIFS(Raw_Data!T2:T18199,Raw_Data!B2:B18199,B15) -> 46224 | D15: =MAX(Raw_Data!T2:T18199)-C15 -> 16 | E15: =COUNTIF(Raw_Data!B2:B18199,B15) -> 3 | F15: =SUMIFS(Raw_Data!E2:E18199,Raw_Data!B2:B18199,B15) -> 1 | G15: =SUMIFS(Raw_Data!F2:F18199,Raw_Data!B2:B18199,B15) -> 0 | H15: =SUMIFS(Raw_Data!I2:I18199,Raw_Data!B2:B18199,B15) -> 0 | I15: =SUMIFS(Raw_Data!L2:L18199,Raw_Data!B2:B18199,B15) -> 0 | J15: =IFERROR(F15/E15,"n/a") -> 0.33333333 | K15: =IFERROR(G15/F15,"n/a") -> 0 | L15: =IFERROR(H15/G15,"n/a") -> n/a | M15: =IFERROR(I15/E15,"n/a") -> 0
B16: Khanna AI | C16: =_xlfn.MINIFS(Raw_Data!T2:T18199,Raw_Data!B2:B18199,B16) -> 46240 | D16: =MAX(Raw_Data!T2:T18199)-C16 -> 0 | E16: =COUNTIF(Raw_Data!B2:B18199,B16) -> 886 | F16: =SUMIFS(Raw_Data!E2:E18199,Raw_Data!B2:B18199,B16) -> 245 | G16: =SUMIFS(Raw_Data!F2:F18199,Raw_Data!B2:B18199,B16) -> 137 | H16: =SUMIFS(Raw_Data!I2:I18199,Raw_Data!B2:B18199,B16) -> 2 | I16: =SUMIFS(Raw_Data!L2:L18199,Raw_Data!B2:B18199,B16) -> 1 | J16: =IFERROR(F16/E16,"n/a") -> 0.2765237 | K16: =IFERROR(G16/F16,"n/a") -> 0.55918367 | L16: =IFERROR(H16/G16,"n/a") -> 0.01459854 | M16: =IFERROR(I16/E16,"n/a") -> 0.0011286682
B17: Khanna- 2W 26th Jul | C17: =_xlfn.MINIFS(Raw_Data!T2:T18199,Raw_Data!B2:B18199,B17) -> 46230 | D17: =MAX(Raw_Data!T2:T18199)-C17 -> 10 | E17: =COUNTIF(Raw_Data!B2:B18199,B17) -> 1546 | F17: =SUMIFS(Raw_Data!E2:E18199,Raw_Data!B2:B18199,B17) -> 1376 | G17: =SUMIFS(Raw_Data!F2:F18199,Raw_Data!B2:B18199,B17) -> 574 | H17: =SUMIFS(Raw_Data!I2:I18199,Raw_Data!B2:B18199,B17) -> 20 | I17: =SUMIFS(Raw_Data!L2:L18199,Raw_Data!B2:B18199,B17) -> 14 | J17: =IFERROR(F17/E17,"n/a") -> 0.89003881 | K17: =IFERROR(G17/F17,"n/a") -> 0.41715116 | L17: =IFERROR(H17/G17,"n/a") -> 0.034843206 | M17: =IFERROR(I17/E17,"n/a") -> 0.0090556274
B18: OLX - Ashwin - 2W - 17 Jul | C18: =_xlfn.MINIFS(Raw_Data!T2:T18199,Raw_Data!B2:B18199,B18) -> 46224 | D18: =MAX(Raw_Data!T2:T18199)-C18 -> 16 | E18: =COUNTIF(Raw_Data!B2:B18199,B18) -> 5182 | F18: =SUMIFS(Raw_Data!E2:E18199,Raw_Data!B2:B18199,B18) -> 962 | G18: =SUMIFS(Raw_Data!F2:F18199,Raw_Data!B2:B18199,B18) -> 372 | H18: =SUMIFS(Raw_Data!I2:I18199,Raw_Data!B2:B18199,B18) -> 9 | I18: =SUMIFS(Raw_Data!L2:L18199,Raw_Data!B2:B18199,B18) -> 4 | J18: =IFERROR(F18/E18,"n/a") -> 0.18564261 | K18: =IFERROR(G18/F18,"n/a") -> 0.38669439 | L18: =IFERROR(H18/G18,"n/a") -> 0.024193548 | M18: =IFERROR(I18/E18,"n/a") -> 0.00077190274
B19: PreOb-Ob Fees Paid 29th Jul (set 1) | C19: =_xlfn.MINIFS(Raw_Data!T2:T18199,Raw_Data!B2:B18199,B19) -> 46232 | D19: =MAX(Raw_Data!T2:T18199)-C19 -> 8 | E19: =COUNTIF(Raw_Data!B2:B18199,B19) -> 1483 | F19: =SUMIFS(Raw_Data!E2:E18199,Raw_Data!B2:B18199,B19) -> 1433 | G19: =SUMIFS(Raw_Data!F2:F18199,Raw_Data!B2:B18199,B19) -> 650 | H19: =SUMIFS(Raw_Data!I2:I18199,Raw_Data!B2:B18199,B19) -> 103 | I19: =SUMIFS(Raw_Data!L2:L18199,Raw_Data!B2:B18199,B19) -> 7 | J19: =IFERROR(F19/E19,"n/a") -> 0.96628456 | K19: =IFERROR(G19/F19,"n/a") -> 0.45359386 | L19: =IFERROR(H19/G19,"n/a") -> 0.15846154 | M19: =IFERROR(I19/E19,"n/a") -> 0.0047201618
B20: PreOb-Ob Fees Paid 29th Jul (set 2) | C20: =_xlfn.MINIFS(Raw_Data!T2:T18199,Raw_Data!B2:B18199,B20) -> 46233 | D20: =MAX(Raw_Data!T2:T18199)-C20 -> 7 | E20: =COUNTIF(Raw_Data!B2:B18199,B20) -> 1558 | F20: =SUMIFS(Raw_Data!E2:E18199,Raw_Data!B2:B18199,B20) -> 1519 | G20: =SUMIFS(Raw_Data!F2:F18199,Raw_Data!B2:B18199,B20) -> 735 | H20: =SUMIFS(Raw_Data!I2:I18199,Raw_Data!B2:B18199,B20) -> 122 | I20: =SUMIFS(Raw_Data!L2:L18199,Raw_Data!B2:B18199,B20) -> 7 | J20: =IFERROR(F20/E20,"n/a") -> 0.97496791 | K20: =IFERROR(G20/F20,"n/a") -> 0.48387097 | L20: =IFERROR(H20/G20,"n/a") -> 0.16598639 | M20: =IFERROR(I20/E20,"n/a") -> 0.0044929397
B21: Single Referral > 7 days- 24th Jul | C21: =_xlfn.MINIFS(Raw_Data!T2:T18199,Raw_Data!B2:B18199,B21) -> 46228 | D21: =MAX(Raw_Data!T2:T18199)-C21 -> 12 | E21: =COUNTIF(Raw_Data!B2:B18199,B21) -> 1500 | F21: =SUMIFS(Raw_Data!E2:E18199,Raw_Data!B2:B18199,B21) -> 1454 | G21: =SUMIFS(Raw_Data!F2:F18199,Raw_Data!B2:B18199,B21) -> 690 | H21: =SUMIFS(Raw_Data!I2:I18199,Raw_Data!B2:B18199,B21) -> 7 | I21: =SUMIFS(Raw_Data!L2:L18199,Raw_Data!B2:B18199,B21) -> 14 | J21: =IFERROR(F21/E21,"n/a") -> 0.96933333 | K21: =IFERROR(G21/F21,"n/a") -> 0.47455296 | L21: =IFERROR(H21/G21,"n/a") -> 0.010144928 | M21: =IFERROR(I21/E21,"n/a") -> 0.0093333333
B23: TOTAL / CHECK | E23: =SUM(E6:E21) -> 18198 | F23: =SUM(F6:F21) -> 11973 | G23: =SUM(G6:G21) -> 5550 | H23: =SUM(H6:H21) -> 348 | I23: =SUM(I6:I21) -> 54
B25: Reconciliation: Leads total above must equal COUNTA of Raw_Data candidate_phone-independent row count (18,198); Attempted/Connected/Interested/FT totals must equal the Funnel_Analysis overall figures. Use this row to catch any mismatch after edits.
B28: Top-3 Cohort Selection
B29: Metric: Lead → FT_after_upload conversion rate (the end business outcome). Filters: Leads ≥ 1,000 (excludes single-event-sized cohorts) AND Age ≥ 5 days (excludes right-censored/immature cohorts; see Data_Quality tab for justification).
B31: Rank | C31: lead_source (cohort) | D31: Leads | E31: Age (days) | F31: FT_after_upload | G31: Lead→FT % | H31: Meets filters?
B32: 1 | C32: =B21 -> Single Referral > 7 days- 24th Jul | D32: =E21 -> 1500 | E32: =D21 -> 12 | F32: =I21 -> 14 | G32: =M21 -> 0.0093333333 | H32: =IF(AND(E21>=1000,D21>=5),"Yes","No") -> Yes
B33: 2 | C33: =B17 -> Khanna- 2W 26th Jul | D33: =E17 -> 1546 | E33: =D17 -> 10 | F33: =I17 -> 14 | G33: =M17 -> 0.0090556274 | H33: =IF(AND(E17>=1000,D17>=5),"Yes","No") -> Yes
B34: 3 | C34: =B19 -> PreOb-Ob Fees Paid 29th Jul (set 1) | D34: =E19 -> 1483 | E34: =D19 -> 8 | F34: =I19 -> 7 | G34: =M19 -> 0.0047201618 | H34: =IF(AND(E19>=1000,D19>=5),"Yes","No") -> Yes

Sheet KPI_Summary
B2: KPI Summary Dashboard
B4: Metric | C4: Result | D4: Interpretation
B5: Total leads | C5: =Funnel_Analysis!C5 -> 18198 | D5: One row = one lead sourced into a cohort.
B6: Total attempted | C6: =Funnel_Analysis!C6 -> 11973 | D6: Leads that received at least one call attempt.
B7: Overall Attempt Rate | C7: =Funnel_Analysis!C6/Funnel_Analysis!C5 -> 0.65792944 | D7: Share of leads ever called the single biggest controllable lever (see Funnel_Analysis).
B8: Overall Connect Rate (of attempted) | C8: =Funnel_Analysis!C7/Funnel_Analysis!C6 -> 0.46354297 | D8: Share of attempted calls that reached the candidate.
B9: Total FT_after_upload | C9: =Funnel_Analysis!C10 -> 54 | D9: Headline business outcome candidate went First Trip.
B10: Overall Lead → FT Rate | C10: =Funnel_Analysis!C10/Funnel_Analysis!C5 -> 0.0029673591 | D10: End-to-end conversion; extremely low base rate (~0.3%) expect small counts to swing this metric.
B11: Number of cohorts | C11: =COUNTA(Cohort_Analysis!B6:B21) -> 16 | D11: lead_source values in the data.
B12: Best cohort (Lead→FT, filtered) | C12: =Cohort_Analysis!C32 -> Single Referral > 7 days- 24th Jul | D12: See Cohort_Analysis Top-3 table for full ranking and filter logic.
B15: Top 3 Cohorts (Lead → FT_after_upload, min. 1,000 leads, age ≥ 5 days)
B16: Rank | C16: Cohort | D16: Lead→FT %
B17: 1 | C17: =Cohort_Analysis!C32 -> Single Referral > 7 days- 24th Jul | D17: =Cohort_Analysis!G32 -> 0.0093333333
B18: 2 | C18: =Cohort_Analysis!C33 -> Khanna- 2W 26th Jul | D18: =Cohort_Analysis!G33 -> 0.0090556274
B19: 3 | C19: =Cohort_Analysis!C34 -> PreOb-Ob Fees Paid 29th Jul (set 1) | D19: =Cohort_Analysis!G34 -> 0.0047201618

Sheet Model_Analysis
B2: FT Driver Analysis, Model Summary
B4: Question addressed (Case Q3): what factors influence the chance a lead reaches FT, and how well can we predict it?
B5: Method: logistic regression (scikit-learn), class_weight='balanced' to counter the severe class imbalance (54 FT events out of 18,197 leads = 0.30%). Evaluated with 5-fold stratified cross-validation so every prediction shown is out-of-fold (the model never saw that row while training).
B6: Target: FT_after_upload (0/1).
B7: Features used: lead_source (cohort, one-hot encoded), Attempted, Connected, tag_filled, Interested, Attempt-per-Lead, and upload-to-first-attempt speed (hours).
B8: Features deliberately EXCLUDED to avoid leakage: OB_after_upload and OB_after_first_attempt (OB is effectively the funnel stage immediately before FT including it would let the model 'cheat' by reading off a near-final-stage outcome instead of finding upstream drivers) and FT_after_first_attempt (a narrower version of the target itself).
B9: This sheet reports the model's summary output computed in Python (full reproducible script referenced in the SQL_Reference / GitHub docs folder) a live in-Excel logistic regression is not attempted because Excel has no native classifier; the underlying counts behind every number here are auditable in Cohort_Analysis.
B11: Confusion Matrix (out-of-fold, 5-fold CV, default 0.5 threshold)
C12: Predicted: No FT | D12: Predicted: FT
B13: Actual: No FT | C13: 11717 | D13: 6426
B14: Actual: FT | C14: 11 | D14: 43
B16: Metric | C16: Value | D16: Interpretation
B17: Precision (FT class) | C17: 0.7% | D17: Extremely low expected given the base rate is only 0.3%; a "balanced" model flags ~35% of all leads as high-risk to catch most true FTs, so most flags are false positives.
B18: Recall / Sensitivity (FT class) | C18: 79.6% | D18: The model catches about 4 out of 5 leads that actually go FT useful for prioritization even though precision is low.
B19: ROC-AUC | C19: 0.798 | D19: Good ranking ability: leads the model scores higher are meaningfully more likely to convert, even though a hard 0.5 cutoff is not usable operationally.
B21: Recommended use: rank leads by predicted probability to prioritize call-center capacity toward the highest-propensity leads, rather than using the model as a hard accept/reject classifier. At this event volume (54 positives), precision at any fixed threshold will remain low; the ranking/AUC signal is the trustworthy part of the output.
B24: Top Drivers (logistic regression coefficients, full-data fit)
B25: Coefficients are on the standardized/one-hot model scale and describe correlation, not causation. lead_source coefficients are relative to the reference cohort; a large positive coefficient means that cohort is associated with materially higher FT odds even after accounting for Attempted/Connected/Interested/tag_filled.
B27: Feature | C27: Coefficient | D27: Direction | E27: Read
B28: Attempted | C28: 5.22 | D28: ▲ Strong positive | E28: Being called at all is the single strongest positive driver consistent with the funnel finding that ~34% of leads are never attempted.
B29: tag_filled | C29: 2.63 | D29: ▲ Strong positive | E29: A completed call-outcome tag correlates with much higher FT odds likely reflects agent engagement quality, not a lever to "add" independently.
B30: Cohort: Khanna- 2W 26th Jul | C30: 2.25 | D30: ▲ Positive | E30: Consistent with this cohort placing in the Top-3 by raw Lead→FT rate.
B31: Cohort: Single Referral > 7 days- 24th Jul | C31: 2.01 | D31: ▲ Positive | E31: Consistent with this cohort placing #1 by raw Lead→FT rate.
B32: Cohort: PreOb-Ob Fees Paid (sets 1 & 2) | C32: 1.52 / 1.27 | D32: ▲ Positive | E32: Both independently-uploaded batches of the same campaign show a positive, similar-sized effect reduces the chance this is random noise from one batch.
B33: Attempt-per-Lead | C33: 0.46 | D33: △ Weak positive | E33: More call attempts associates with slightly higher odds small effect once Attempted is already in the model.
B34: Connected | C34: -2.03 | D34: ▼ Negative | E34: Counter-intuitive; likely a statistical suppressor effect from collinearity with lead_source and Attempted, and from the finding that most FT/OB events bypass the normal Connected→Interested path. Not a recommendation to avoid connecting candidates.
B35: Interested | C35: -2.05 | D35: ▼ Negative | E35: Same caution as Connected reflects that the Interested tag is inconsistently applied (see Data_Quality) rather than a genuine negative causal effect.
B36: Cohort: 2W3W batches / AI Connected band Not Interested | C36: -3.5 to -4.3 | D36: ▼ Negative | E36: These cohorts recorded zero FT events despite being mature (≥19 days) a genuine, not censoring-driven, weak-performance signal.

Sheet Charts
B2: Charts: Funnel & Cohort Visuals

Sheet SQL_Reference
B2: SQL Reference
B4: The full, commented SQL analysis (BigQuery Standard SQL) is provided as a standalone file, vahan_pa.sql, in the project /sql folder. It reproduces every metric in this workbook directly from the raw_data table so Excel and SQL results can be cross-checked.
B5: Query list:
B6: 1. Data profiling - row counts, distinct cohorts/dates, missing keys
B7: 2. Grain / cardinality check - confirms no true duplicate (phone+cohort+date) rows
B8: 3. Overall funnel conversion (Lead -> Attempted -> Connected -> Interested -> OB -> FT)
B9: 4. Cohort-level aggregation (the required 'aggregate table' output for Case Question 2)
B10: 5. Top-3 cohort selection with minimum-size and maturity filters (Case Question 1)
B11: 6. Mature vs. immature cohort comparison (right-censoring check)
B12: 7. Speed-to-first-attempt vs. connect-rate analysis
B13: 8. Interested-flag consistency / leakage check ahead of Interested/OB/FT
B14: 9. Data-quality validation funnel-state hierarchy and impossible-value checks
... B16: 11. Duplicate-candidate (re-targeting) check
